Workbook

Sheet Cover
B4: F. Hoffmann-La Roche Ltd
B7: Roche Holding AG | SIX: ROP
B10: Discounted Cash Flow Analysis
B13: ="Valuation date: "&TEXT(Assumptions!$D$7,"d mmmm yyyy") -> Valuation date: 2 September 2026
B15: ="Scenario shown: "&Assumptions!$E$4&" | CHF millions unless stated" -> Scenario shown: Base case | CHF millions unless stated
B18: ="Implied value per share (midpoint): CHF "&TEXT(DCF!$C$50,"0.00")&" vs. current CHF "&TEXT(Assumptions!$D$8,"0.00") -> Implied value per share (midpoint): CHF 421.63 vs. current CHF 357.00
B22: Sources: Roche Annual Reports and Finance Reports 2023–2025; market data as noted on the Assumptions tab.
B26: Colour legend
B27: 1,234.5 | C27: Blue – hardcoded input (reported figure or assumption)
B28: 1,234.5 | C28: Black – formula calculated on the same tab
B29: 1,234.5 | C29: Green – formula linking to another tab
C30: Yellow fill – key output or scenario lever
C31: Red fill on a check row – model integrity error
B33: Tabs: Cover · Assumptions · Historicals · Operating Model · WACC · DCF · Sensitivity · Charts

Sheet Assumptions
B1: Assumptions
B2: All model drivers. Blue = hardcoded input. Change the scenario in cell D4; the Live column feeds the entire model.
B4: Scenario selector (1 = Base, 2 = Bull, 3 = Bear) | D4: 1 | E4: =CHOOSE($D$4,"Base case","Bull case","Bear case") -> Base case
B6: Market data & valuation inputs | C6: Unit | D6: Value | H6: Source / comment
B7: Valuation date | C7: date | D7: =DATE(2026,9,2) -> 46267 | H7: User-specified valuation date
B8: Current share price (ROP) | C8: CHF | D8: 357 | H8: Nearest dated SIX close found (7 Sep 2026, Stockopedia); exact 2 Sep 2026 close not retrieved – verify on SIX
B9: 52-week low | C9: CHF | D9: 254 | H9: Morningstar ROP quote page (52-week range), late Sep 2026 – verify vs. 2 Sep 2026 window
B10: 52-week high | C10: CHF | D10: 375.8 | H10: Morningstar ROP quote page (52-week range), late Sep 2026 – verify vs. 2 Sep 2026 window
B11: Observed raw beta (vs. local index) | C11: x | D11: 0.35 | H11: stockanalysis.com, SWX:RO / ROP (beta 0.34–0.35)
B12: Peer EV / 2026E EBITDA – low | C12: x | D12: 10.5 | H12: Assumption: EU/US large-cap pharma trading range; not from annual reports
B13: Peer EV / 2026E EBITDA – high | C13: x | D13: 13.5 | H13: Assumption: EU/US large-cap pharma trading range; not from annual reports
B14: Sensitivity step – WACC | C14: % | D14: 0.0025 | H14: Grid increment
B15: Sensitivity step – terminal growth | C15: % | D15: 0.0025 | H15: Grid increment
B16: Sensitivity step – exit multiple | C16: x | D16: 0.5 | H16: Grid increment
B18: Operating & valuation drivers | C18: Unit | D18: Base | E18: Bull | F18: Bear | G18: Live | H18: Source / rationale
B19: Revenue
B20: Pharmaceuticals sales growth – 2026E | C20: % | D20: 0.04 | E20: 0.06 | F20: 0.015 | G20: =CHOOSE($D$4,D20,E20,F20) -> 0.04 | H20: Hist. CHF: +4.3% (24A), +3.2% (25A); 2026 guide mid-single digit CER, CHF translation drag; bear = LOE / pricing (IRA, MFN)
B21: Pharmaceuticals sales growth – 2027E | C21: % | D21: 0.045 | E21: 0.065 | F21: 0.01 | G21: =CHOOSE($D$4,D21,E21,F21) -> 0.045
B22: Pharmaceuticals sales growth – 2028E | C22: % | D22: 0.04 | E22: 0.06 | F22: 0.005 | G22: =CHOOSE($D$4,D22,E22,F22) -> 0.04
B23: Pharmaceuticals sales growth – 2029E | C23: % | D23: 0.035 | E23: 0.055 | F23: 0.005 | G23: =CHOOSE($D$4,D23,E23,F23) -> 0.035
B24: Pharmaceuticals sales growth – 2030E | C24: % | D24: 0.03 | E24: 0.05 | F24: 0.01 | G24: =CHOOSE($D$4,D24,E24,F24) -> 0.03
B25: Diagnostics sales growth – 2026E | C25: % | D25: 0.015 | E25: 0.03 | F25: 0 | G25: =CHOOSE($D$4,D25,E25,F25) -> 0.015 | H25: Hist. CHF: –0.9% (24A), –3.3% (25A); China volume-based procurement drag fading
B26: Diagnostics sales growth – 2027E | C26: % | D26: 0.03 | E26: 0.045 | F26: 0.01 | G26: =CHOOSE($D$4,D26,E26,F26) -> 0.03
B27: Diagnostics sales growth – 2028E | C27: % | D27: 0.035 | E27: 0.05 | F27: 0.015 | G27: =CHOOSE($D$4,D27,E27,F27) -> 0.035
B28: Diagnostics sales growth – 2029E | C28: % | D28: 0.035 | E28: 0.05 | F28: 0.02 | G28: =CHOOSE($D$4,D28,E28,F28) -> 0.035
B29: Diagnostics sales growth – 2030E | C29: % | D29: 0.035 | E29: 0.05 | F29: 0.02 | G29: =CHOOSE($D$4,D29,E29,F29) -> 0.035
B30: Other revenue – % of Group sales | C30: % | D30: 0.03 | E30: 0.032 | F30: 0.028 | G30: =CHOOSE($D$4,D30,E30,F30) -> 0.03 | H30: Hist.: 2.9% / 3.1% / 3.0% (royalties, collaboration income)
B31: Profitability
B32: Adjusted EBITDA margin – 2026E | C32: % | D32: 0.392 | E32: 0.4 | F32: 0.38 | G32: =CHOOSE($D$4,D32,E32,F32) -> 0.392 | H32: Adj. EBITDA = core operating profit + depreciation (PPE + right-of-use). Hist.: 36.4% / 37.7% / 38.7%
B33: Adjusted EBITDA margin – 2027E | C33: % | D33: 0.396 | E33: 0.408 | F33: 0.375 | G33: =CHOOSE($D$4,D33,E33,F33) -> 0.396
B34: Adjusted EBITDA margin – 2028E | C34: % | D34: 0.4 | E34: 0.415 | F34: 0.37 | G34: =CHOOSE($D$4,D34,E34,F34) -> 0.4
B35: Adjusted EBITDA margin – 2029E | C35: % | D35: 0.402 | E35: 0.42 | F35: 0.365 | G35: =CHOOSE($D$4,D35,E35,F35) -> 0.402
B36: Adjusted EBITDA margin – 2030E | C36: % | D36: 0.404 | E36: 0.425 | F36: 0.36 | G36: =CHOOSE($D$4,D36,E36,F36) -> 0.404
B37: D&A (incl. amortisation) – % of revenue | C37: % | D37: 0.053 | E37: 0.052 | F37: 0.055 | G37: =CHOOSE($D$4,D37,E37,F37) -> 0.053 | H37: Hist.: 5.7% / 5.5% / 5.3%
B38: Stock-based compensation – % of revenue (memo) | C38: % | D38: 0.014 | E38: 0.013 | F38: 0.015 | G38: =CHOOSE($D$4,D38,E38,F38) -> 0.014 | H38: Hist.: 1.4% each year. Treated as a cash-like cost: already inside EBITDA, NOT added back
B39: Investment & working capital
B40: Capex (PPE + intangibles) – % of revenue | C40: % | D40: 0.085 | E40: 0.08 | F40: 0.095 | G40: =CHOOSE($D$4,D40,E40,F40) -> 0.085 | H40: Hist.: 7.7% / 8.0% / 9.1%
B41: Cost of sales – % of revenue (for WC days) | C41: % | D41: 0.26 | E41: 0.255 | F41: 0.268 | G41: =CHOOSE($D$4,D41,E41,F41) -> 0.26 | H41: IFRS cost of sales. Hist.: 27.1% / 26.1% / 26.3%
B42: Receivable days (DSO, on revenue) | C42: days | D42: 66 | E42: 63 | F42: 70 | G42: =CHOOSE($D$4,D42,E42,F42) -> 66 | H42: Hist.: 66.6 / 66.1 / 66.3
B43: Inventory days (DIO, on cost of sales) | C43: days | D43: 165 | E43: 155 | F43: 175 | G43: =CHOOSE($D$4,D43,E43,F43) -> 165 | H43: Hist.: 172.9 / 170.5 / 164.0
...

Sheet Historicals
B1: Historicals
B2: CHF millions, years ended 31 December. Source: Roche Finance Reports 2024 (2023 restated) and 2025. Blue = as reported.
C4: 2023A | D4: 2024A | E4: 2025A | G4: % rev 23A | H4: % rev 24A | I4: % rev 25A | K4: YoY 24A | L4: YoY 25A | M4: Source
B6: Income statement
B7: Pharmaceuticals sales | C7: 44265 | D7: 46171 | E7: 47669 | G7: =IF(C$11=0,0,C7/C$11) -> 0.7323671 | H7: =IF(D$11=0,0,D7/D$11) -> 0.73997916 | I7: =IF(E$11=0,0,E7/E$11) -> 0.75239914 | K7: =IF(C7=0,0,D7/C7-1) -> 0.04305885 | L7: =IF(D7=0,0,E7/D7-1) -> 0.032444608 | M7: FR24 p.48 (restated) / FR25 p.48
B8: Diagnostics sales | C8: 14451 | D8: 14324 | E8: 13847 | G8: =IF(C$11=0,0,C8/C$11) -> 0.23909267 | H8: =IF(D$11=0,0,D8/D$11) -> 0.22956968 | I8: =IF(E$11=0,0,E8/E$11) -> 0.21855862 | K8: =IF(C8=0,0,D8/C8-1) -> -0.0087883191 | L8: =IF(D8=0,0,E8/D8-1) -> -0.033300754 | M8: FR24 p.48 (restated) / FR25 p.48
B9: Group sales | C9: =C7+C8 -> 58716 | D9: =D7+D8 -> 60495 | E9: =E7+E8 -> 61516 | G9: =IF(C$11=0,0,C9/C$11) -> 0.97145977 | H9: =IF(D$11=0,0,D9/D$11) -> 0.96954884 | I9: =IF(E$11=0,0,E9/E$11) -> 0.97095776 | K9: =IF(C9=0,0,D9/C9-1) -> 0.030298385 | L9: =IF(D9=0,0,E9/D9-1) -> 0.016877428
B10: Other revenue | C10: 1725 | D10: 1900 | E10: 1840 | G10: =IF(C$11=0,0,C10/C$11) -> 0.028540229 | H10: =IF(D$11=0,0,D10/D$11) -> 0.030451158 | I10: =IF(E$11=0,0,E10/E$11) -> 0.029042238 | K10: =IF(C10=0,0,D10/C10-1) -> 0.10144928 | L10: =IF(D10=0,0,E10/D10-1) -> -0.031578947 | M10: Consolidated income statement
B11: Revenue | C11: =C9+C10 -> 60441 | D11: =D9+D10 -> 62395 | E11: =E9+E10 -> 63356 | G11: =IF(C$11=0,0,C11/C$11) -> 1 | H11: =IF(D$11=0,0,D11/D$11) -> 1 | I11: =IF(E$11=0,0,E11/E$11) -> 1 | K11: =IF(C11=0,0,D11/C11-1) -> 0.032329048 | L11: =IF(D11=0,0,E11/D11-1) -> 0.015401875
B12: Cost of sales | C12: -16357 | D12: -16283 | E12: -16645 | G12: =IF(C$11=0,0,C12/C$11) -> -0.27062755 | H12: =IF(D$11=0,0,D12/D$11) -> -0.26096642 | I12: =IF(E$11=0,0,E12/E$11) -> -0.26272176 | K12: =IF(C12=0,0,D12/C12-1) -> -0.004524057 | L12: =IF(D12=0,0,E12/D12-1) -> 0.022231775
B13: Gross profit | C13: =C11+C12 -> 44084 | D13: =D11+D12 -> 46112 | E13: =E11+E12 -> 46711 | G13: =IF(C$11=0,0,C13/C$11) -> 0.72937245 | H13: =IF(D$11=0,0,D13/D$11) -> 0.73903358 | I13: =IF(E$11=0,0,E13/E$11) -> 0.73727824 | K13: =IF(C13=0,0,D13/C13-1) -> 0.046003085 | L13: =IF(D13=0,0,E13/D13-1) -> 0.012990111
B14: Research and development | C14: -14200 | D14: -15304 | E14: -13352 | G14: =IF(C$11=0,0,C14/C$11) -> -0.23493986 | H14: =IF(D$11=0,0,D14/D$11) -> -0.24527606 | I14: =IF(E$11=0,0,E14/E$11) -> -0.21074563 | K14: =IF(C14=0,0,D14/C14-1) -> 0.077746479 | L14: =IF(D14=0,0,E14/D14-1) -> -0.12754835
B15: Selling, general and administration | C15: -14881 | D15: -14896 | E15: -15161 | G15: =IF(C$11=0,0,C15/C$11) -> -0.24620704 | H15: =IF(D$11=0,0,D15/D$11) -> -0.23873708 | I15: =IF(E$11=0,0,E15/E$11) -> -0.23929857 | K15: =IF(C15=0,0,D15/C15-1) -> 0.0010079968 | L15: =IF(D15=0,0,E15/D15-1) -> 0.017790011
B16: Other operating income (expense) | C16: 392 | D16: -2495 | E16: 278 | G16: =IF(C$11=0,0,C16/C$11) -> 0.0064856637 | H16: =IF(D$11=0,0,D16/D$11) -> -0.039987178 | I16: =IF(E$11=0,0,E16/E$11) -> 0.0043879033 | K16: =IF(C16=0,0,D16/C16-1) -> -7.3647959 | L16: =IF(D16=0,0,E16/D16-1) -> -1.1114228 | M16: 2024 incl. CHF 4.7bn goodwill/intangible impairments
B17: Operating profit (IFRS) | C17: =C13+C14+C15+C16 -> 15395 | D17: =D13+D14+D15+D16 -> 13417 | E17: =E13+E14+E15+E16 -> 18476 | G17: =IF(C$11=0,0,C17/C$11) -> 0.25471121 | H17: =IF(D$11=0,0,D17/D$11) -> 0.21503326 | I17: =IF(E$11=0,0,E17/E$11) -> 0.29162195 | K17: =IF(C17=0,0,D17/C17-1) -> -0.12848327 | L17: =IF(D17=0,0,E17/D17-1) -> 0.37705896
B18: Financing costs | C18: -996 | D18: -1412 | E18: -1349 | G18: =IF(C$11=0,0,C18/C$11) -> -0.01647888 | H18: =IF(D$11=0,0,D18/D$11) -> -0.022630018 | I18: =IF(E$11=0,0,E18/E$11) -> -0.02129238 | K18: =IF(C18=0,0,D18/C18-1) -> 0.41767068 | L18: =IF(D18=0,0,E18/D18-1) -> -0.044617564
B19: Other financial income (expense) | C19: -320 | D19: -212 | E19: -154 | G19: =IF(C$11=0,0,C19/C$11) -> -0.0052944194 | H19: =IF(D$11=0,0,D19/D$11) -> -0.0033977081 | I19: =IF(E$11=0,0,E19/E$11) -> -0.002430709 | K19: =IF(C19=0,0,D19/C19-1) -> -0.3375 | L19: =IF(D19=0,0,E19/D19-1) -> -0.27358491
B20: Profit before taxes | C20: =C17+C18+C19 -> 14079 | D20: =D17+D18+D19 -> 11793 | E20: =E17+E18+E19 -> 16973 | G20: =IF(C$11=0,0,C20/C$11) -> 0.23293791 | H20: =IF(D$11=0,0,D20/D$11) -> 0.18900553 | I20: =IF(E$11=0,0,E20/E$11) -> 0.26789886 | K20: =IF(C20=0,0,D20/C20-1) -> -0.16236949 | L20: =IF(D20=0,0,E20/D20-1) -> 0.43924362
B21: Income taxes | C21: -1721 | D21: -2606 | E21: -3174 | G21: =IF(C$11=0,0,C21/C$11) -> -0.028474049 | H21: =IF(D$11=0,0,D21/D$11) -> -0.041766167 | I21: =IF(E$11=0,0,E21/E$11) -> -0.05009786 | K21: =IF(C21=0,0,D21/C21-1) -> 0.51423591 | L21: =IF(D21=0,0,E21/D21-1) -> 0.21795856
B22: Net income | C22: =C20+C21 -> 12358 | D22: =D20+D21 -> 9187 | E22: =E20+E21 -> 13799 | G22: =IF(C$11=0,0,C22/C$11) -> 0.20446386 | H22: =IF(D$11=0,0,D22/D$11) -> 0.14723936 | I22: =IF(E$11=0,0,E22/E$11) -> 0.217801 | K22: =IF(C22=0,0,D22/C22-1) -> -0.25659492 | L22: =IF(D22=0,0,E22/D22-1) -> 0.50201372
B23: Attributable to non-controlling interests | C23: -860 | D23: -910 | E23: -919 | G23: =IF(C$11=0,0,C23/C$11) -> -0.014228752 | H23: =IF(D$11=0,0,D23/D$11) -> -0.014584502 | I23: =IF(E$11=0,0,E23/E$11) -> -0.014505335 | K23: =IF(C23=0,0,D23/C23-1) -> 0.058139535 | L23: =IF(D23=0,0,E23/D23-1) -> 0.0098901099
B24: Net income attributable to Roche shareholders | C24: =C22+C23 -> 11498 | D24: =D22+D23 -> 8277 | E24: =E22+E23 -> 12880 | G24: =IF(C$11=0,0,C24/C$11) -> 0.19023511 | H24: =IF(D$11=0,0,D24/D$11) -> 0.13265486 | I24: =IF(E$11=0,0,E24/E$11) -> 0.20329566 | K24: =IF(C24=0,0,D24/C24-1) -> -0.28013568 | L24: =IF(D24=0,0,E24/D24-1) -> 0.55611937
B25: Effective tax rate (IFRS) | C25: =IF(C20=0,0,-C21/C20) -> 0.1222388 | D25: =IF(D20=0,0,-D21/D20) -> 0.22097855 | E25: =IF(E20=0,0,-E21/E20) -> 0.18700289
B27: Per share
B28: Weighted avg. shares & NES outstanding (m) | C28: 799 | D28: 797 | E28: 796 | K28: =IF(C28=0,0,D28/C28-1) -> -0.0025031289 | L28: =IF(D28=0,0,E28/D28-1) -> -0.0012547051 | M28: Note 29
B29: Dilution – equity compensation plans (m) | C29: 5 | D29: 5 | E29: 7 | K29: =IF(C29=0,0,D29/C29-1) -> 0 | L29: =IF(D29=0,0,E29/D29-1) -> 0.4 | M29: Note 29
B30: Diluted shares (m) | C30: =C28+C29 -> 804 | D30: =D28+D29 -> 802 | E30: =E28+E29 -> 803 | K30: =IF(C30=0,0,D30/C30-1) -> -0.0024875622 | L30: =IF(D30=0,0,E30/D30-1) -> 0.0012468828
B31: Diluted EPS (CHF) – calculated | C31: =C24/C30 -> 14.300995 | D31: =D24/D30 -> 10.320449 | E31: =E24/E30 -> 16.039851 | K31: =IF(C31=0,0,D31/C31-1) -> -0.2783405 | L31: =IF(D31=0,0,E31/D31-1) -> 0.55418148
B32: Diluted EPS (CHF) – as reported | C32: 14.31 | D32: 10.31 | E32: 16.04 | K32: =IF(C32=0,0,D32/C32-1) -> -0.27952481 | L32: =IF(D32=0,0,E32/D32-1) -> 0.5557711 | M32: Note 29 (difference = share rounding)
B33: Dividend per share (CHF) | C33: 9.6 | D33: 9.7 | E33: 9.8 | K33: =IF(C33=0,0,D33/C33-1) -> 0.010416667 | L33: =IF(D33=0,0,E33/D33-1) -> 0.010309278 | M33: Annual Reports
B35: Segment split
B36: Pharmaceuticals operating profit | C36: 17911 | D36: 15587 | E36: 21666 | G36: =IF(C$11=0,0,C36/C$11) -> 0.29633858 | H36: =IF(D$11=0,0,D36/D$11) -> 0.24981168 | I36: =IF(E$11=0,0,E36/E$11) -> 0.34197235 | K36: =IF(C36=0,0,D36/C36-1) -> -0.12975267 | L36: =IF(D36=0,0,E36/D36-1) -> 0.39000449
B37: Diagnostics operating profit | C37: 1392 | D37: 1946 | E37: 1070 | G37: =IF(C$11=0,0,C37/C$11) -> 0.023030724 | H37: =IF(D$11=0,0,D37/D$11) -> 0.031188397 | I37: =IF(E$11=0,0,E37/E$11) -> 0.016888692 | K37: =IF(C37=0,0,D37/C37-1) -> 0.39798851 | L37: =IF(D37=0,0,E37/D37-1) -> -0.45015416
B38: Corporate | C38: -3908 | D38: -4116 | E38: -4260 | G38: =IF(C$11=0,0,C38/C$11) -> -0.064658096 | H38: =IF(D$11=0,0,D38/D$11) -> -0.065966824 | I38: =IF(E$11=0,0,E38/E$11) -> -0.067239093 | K38: =IF(C38=0,0,D38/C38-1) -> 0.053224156 | L38: =IF(D38=0,0,E38/D38-1) -> 0.034985423
B39: Check: segments vs. Group operating profit | C39: =C36+C37+C38-C17 -> 0 | D39: =D36+D37+D38-D17 -> 0 | E39: =E36+E37+E38-E17 -> 0
B40: Pharmaceuticals – operating margin on sales | C40: =C36/C7 -> 0.4046312 | D40: =D36/D7 -> 0.33759286 | E40: =E36/E7 -> 0.45450922
B41: Diagnostics – operating margin on sales | C41: =C37/C8 -> 0.096325514 | D41: =D37/D8 -> 0.13585591 | E41: =E37/E8 -> 0.077273056
B42: Pharmaceuticals – share of Group sales | C42: =C7/C9 -> 0.7538831 | D42: =D7/D9 -> 0.7632201 | E42: =E7/E9 -> 0.77490409
B44: Adjusted EBITDA build
B45: Core operating profit | C45: 19240 | D45: 20823 | E45: 21833 | G45: =IF(C$11=0,0,C45/C$11) -> 0.31832696 | H45: =IF(D$11=0,0,D45/D$11) -> 0.33372866 | I45: =IF(E$11=0,0,E45/E$11) -> 0.34460825 | K45: =IF(C45=0,0,D45/C45-1) -> 0.082276507 | L45: =IF(D45=0,0,E45/D45-1) -> 0.048504058 | M45: Finance Review, core results
...

Sheet Operating Model
B1: Operating Model
B2: CHF millions. Five-year forecast from revenue to unlevered free cash flow. All drivers from the Assumptions tab (Live column). | E2: ="Scenario: "&Assumptions!$E$4 -> Scenario: Base case
C4: 2025A | D4: 2026E | E4: 2027E | F4: 2028E | G4: 2029E | H4: 2030E
B6: Drivers (linked from Assumptions – Live)
B7: Pharmaceuticals sales growth | D7: =Assumptions!$G$20 -> 0.04 | E7: =Assumptions!$G$21 -> 0.045 | F7: =Assumptions!$G$22 -> 0.04 | G7: =Assumptions!$G$23 -> 0.035 | H7: =Assumptions!$G$24 -> 0.03
B8: Diagnostics sales growth | D8: =Assumptions!$G$25 -> 0.015 | E8: =Assumptions!$G$26 -> 0.03 | F8: =Assumptions!$G$27 -> 0.035 | G8: =Assumptions!$G$28 -> 0.035 | H8: =Assumptions!$G$29 -> 0.035
B9: Other revenue – % of Group sales | D9: =Assumptions!$G$30 -> 0.03 | E9: =Assumptions!$G$30 -> 0.03 | F9: =Assumptions!$G$30 -> 0.03 | G9: =Assumptions!$G$30 -> 0.03 | H9: =Assumptions!$G$30 -> 0.03
B10: Adjusted EBITDA margin | D10: =Assumptions!$G$32 -> 0.392 | E10: =Assumptions!$G$33 -> 0.396 | F10: =Assumptions!$G$34 -> 0.4 | G10: =Assumptions!$G$35 -> 0.402 | H10: =Assumptions!$G$36 -> 0.404
B11: D&A – % of revenue | D11: =Assumptions!$G$37 -> 0.053 | E11: =Assumptions!$G$37 -> 0.053 | F11: =Assumptions!$G$37 -> 0.053 | G11: =Assumptions!$G$37 -> 0.053 | H11: =Assumptions!$G$37 -> 0.053
B12: Capex – % of revenue | D12: =Assumptions!$G$40 -> 0.085 | E12: =Assumptions!$G$40 -> 0.085 | F12: =Assumptions!$G$40 -> 0.085 | G12: =Assumptions!$G$40 -> 0.085 | H12: =Assumptions!$G$40 -> 0.085
B13: Cost of sales – % of revenue | D13: =Assumptions!$G$41 -> 0.26 | E13: =Assumptions!$G$41 -> 0.26 | F13: =Assumptions!$G$41 -> 0.26 | G13: =Assumptions!$G$41 -> 0.26 | H13: =Assumptions!$G$41 -> 0.26
B14: Receivable days | D14: =Assumptions!$G$42 -> 66 | E14: =Assumptions!$G$42 -> 66 | F14: =Assumptions!$G$42 -> 66 | G14: =Assumptions!$G$42 -> 66 | H14: =Assumptions!$G$42 -> 66
B15: Inventory days | D15: =Assumptions!$G$43 -> 165 | E15: =Assumptions!$G$43 -> 165 | F15: =Assumptions!$G$43 -> 165 | G15: =Assumptions!$G$43 -> 165 | H15: =Assumptions!$G$43 -> 165
B16: Payable days | D16: =Assumptions!$G$44 -> 120 | E16: =Assumptions!$G$44 -> 120 | F16: =Assumptions!$G$44 -> 120 | G16: =Assumptions!$G$44 -> 120 | H16: =Assumptions!$G$44 -> 120
B17: Cash tax rate | C17: =Historicals!$E$25 -> 0.18700289 | D17: =Assumptions!$G$46 -> 0.19 | E17: =Assumptions!$G$46 -> 0.19 | F17: =Assumptions!$G$46 -> 0.19 | G17: =Assumptions!$G$46 -> 0.19 | H17: =Assumptions!$G$46 -> 0.19
B18: SBC – % of revenue | D18: =Assumptions!$G$38 -> 0.014 | E18: =Assumptions!$G$38 -> 0.014 | F18: =Assumptions!$G$38 -> 0.014 | G18: =Assumptions!$G$38 -> 0.014 | H18: =Assumptions!$G$38 -> 0.014
B20: Revenue build
B21: Pharmaceuticals sales | C21: =Historicals!$E$7 -> 47669 | D21: =C21*(1+D7) -> 49575.76 | E21: =D21*(1+E7) -> 51806.669 | F21: =E21*(1+F7) -> 53878.936 | G21: =F21*(1+G7) -> 55764.699 | H21: =G21*(1+H7) -> 57437.64
B22: Diagnostics sales | C22: =Historicals!$E$8 -> 13847 | D22: =C22*(1+D8) -> 14054.705 | E22: =D22*(1+E8) -> 14476.346 | F22: =E22*(1+F8) -> 14983.018 | G22: =F22*(1+G8) -> 15507.424 | H22: =G22*(1+H8) -> 16050.184
B23: Group sales | C23: =C21+C22 -> 61516 | D23: =D21+D22 -> 63630.465 | E23: =E21+E22 -> 66283.015 | F23: =F21+F22 -> 68861.954 | G23: =G21+G22 -> 71272.123 | H23: =H21+H22 -> 73487.823
B24: Other revenue | C24: =Historicals!$E$10 -> 1840 | D24: =D23*D9 -> 1908.914 | E24: =E23*E9 -> 1988.4905 | F24: =F23*F9 -> 2065.8586 | G24: =G23*G9 -> 2138.1637 | H24: =H23*H9 -> 2204.6347
B25: Revenue | C25: =C23+C24 -> 63356 | D25: =D23+D24 -> 65539.379 | E25: =E23+E24 -> 68271.506 | F25: =F23+F24 -> 70927.813 | G25: =G23+G24 -> 73410.286 | H25: =H23+H24 -> 75692.458
B26: Revenue growth | C26: =C25/Historicals!$D$11-1 -> 0.015401875 | D26: =D25/C25-1 -> 0.034462071 | E26: =E25/D25-1 -> 0.041686798 | F26: =F25/E25-1 -> 0.03890799 | G26: =G25/F25-1 -> 0.035 | H26: =H25/G25-1 -> 0.031087902
B28: Profitability
B29: Adjusted EBITDA | C29: =Historicals!$E$56 -> 24543 | D29: =D25*D10 -> 25691.437 | E29: =E25*E10 -> 27035.516 | F29: =F25*F10 -> 28371.125 | G29: =G25*G10 -> 29510.935 | H29: =H25*H10 -> 30579.753
B30: Adjusted EBITDA margin | C30: =C29/C25 -> 0.38738241 | D30: =D29/D25 -> 0.392 | E30: =E29/E25 -> 0.396 | F30: =F29/F25 -> 0.4 | G30: =G29/G25 -> 0.402 | H30: =H29/H25 -> 0.404
B31: Depreciation & amortisation | C31: =-Historicals!$E$49 -> -3386 | D31: =-D25*D11 -> -3473.5871 | E31: =-E25*E11 -> -3618.3898 | F31: =-F25*F11 -> -3759.1741 | G31: =-G25*G11 -> -3890.7452 | H31: =-H25*H11 -> -4011.7003
B32: EBIT (adjusted, after amortisation) | C32: =C29+C31 -> 21157 | D32: =D29+D31 -> 22217.849 | E32: =E29+E31 -> 23417.126 | F32: =F29+F31 -> 24611.951 | G32: =G29+G31 -> 25620.19 | H32: =H29+H31 -> 26568.053
B33: EBIT margin | C33: =C32/C25 -> 0.33393838 | D33: =D32/D25 -> 0.339 | E33: =E32/E25 -> 0.343 | F33: =F32/F25 -> 0.347 | G33: =G32/G25 -> 0.349 | H33: =H32/H25 -> 0.351
B34: Taxes on EBIT | C34: =-C32*C17 -> -3956.4201 | D34: =-D32*D17 -> -4221.3914 | E34: =-E32*E17 -> -4449.254 | F34: =-F32*F17 -> -4676.2707 | G34: =-G32*G17 -> -4867.8361 | H34: =-H32*H17 -> -5047.93
B35: NOPAT | C35: =C32+C34 -> 17200.58 | D35: =D32+D34 -> 17996.458 | E35: =E32+E34 -> 18967.872 | F35: =F32+F34 -> 19935.68 | G35: =G32+G34 -> 20752.354 | H35: =H32+H34 -> 21520.123
B37: Working capital
B38: Cost of sales (for days calculation) | C38: =-Historicals!$E$12 -> 16645 | D38: =D25*D13 -> 17040.239 | E38: =E25*E13 -> 17750.592 | F38: =F25*F13 -> 18441.231 | G38: =G25*G13 -> 19086.674 | H38: =H25*H13 -> 19680.039
B39: Accounts receivable | C39: =Historicals!$E$81 -> 11506 | D39: =D25*D14/365 -> 11850.956 | E39: =E25*E14/365 -> 12344.985 | F39: =F25*F14/365 -> 12825.303 | G39: =G25*G14/365 -> 13274.189 | H39: =H25*H14/365 -> 13686.855
B40: Inventories | C40: =Historicals!$E$80 -> 7479 | D40: =D38*D15/365 -> 7703.1215 | E40: =E38*E15/365 -> 8024.24 | F40: =F38*F15/365 -> 8336.447 | G40: =G38*G15/365 -> 8628.2227 | H40: =H38*H15/365 -> 8896.456
B41: Accounts payable | C41: =Historicals!$E$98 -> 5779 | D41: =D38*D16/365 -> 5602.2702 | E41: =E38*E16/365 -> 5835.8109 | F41: =F38*F16/365 -> 6062.8706 | G41: =G38*G16/365 -> 6275.071 | H41: =H38*H16/365 -> 6470.1498
B42: Trade working capital | C42: =C39+C40-C41 -> 13206 | D42: =D39+D40-D41 -> 13951.808 | E42: =E39+E40-E41 -> 14533.414 | F42: =F39+F40-F41 -> 15098.88 | G42: =G39+G40-G41 -> 15627.34 | H42: =H39+H40-H41 -> 16113.162
B43: (Increase) / decrease in working capital | C43: =Historicals!$D$118-C42 -> 803 | D43: =C42-D42 -> -745.80752 | E43: =D42-E42 -> -581.60618 | F43: =E42-F42 -> -565.46591 | G43: =F42-G42 -> -528.46079 | H43: =G42-H42 -> -485.82123
B45: Unlevered free cash flow
B46: NOPAT | C46: =C35 -> 17200.58 | D46: =D35 -> 17996.458 | E46: =E35 -> 18967.872 | F46: =F35 -> 19935.68 | G46: =G35 -> 20752.354 | H46: =H35 -> 21520.123
...

Sheet WACC
B1: WACC
B2: Cost of capital. CAPM cost of equity, after-tax cost of debt, market-value capital structure.
B4: Item | C4: Value | E4: Comment
B6: Capital structure (market values)
B7: Share price (CHF) | C7: =Assumptions!$D$8 -> 357
B8: Diluted shares (m) | C8: =Historicals!$E$30 -> 803 | E8: FY2025 weighted diluted (Note 29)
B9: Market capitalisation (E) | C9: =C7*C8 -> 286671
B10: Total debt | C10: =Historicals!$E$111 -> 31636 | E10: 31 Dec 2025, latest audited balance sheet
B11: Lease liabilities | C11: =Historicals!$E$110 -> 1555
B12: Total debt incl. leases (D) | C12: =C10+C11 -> 33191
B13: Enterprise capital (D + E) | C13: =C9+C12 -> 319862
B14: Debt / equity | C14: =C12/C9 -> 0.11578081
B15: Weight of debt D / (D + E) | C15: =C12/C13 -> 0.10376662
B16: Weight of equity E / (D + E) | C16: =C9/C13 -> 0.89623338
B18: Beta
B19: Tax rate (for levering) | C19: =Assumptions!$G$46 -> 0.19
B20: Observed raw beta (local index) | C20: =Assumptions!$D$11 -> 0.35
B21: Blume-adjusted beta (0.67 × raw + 0.33) | C21: =0.67*C20+0.33 -> 0.5645 | E21: Standard Bloomberg adjustment
B22: Implied unlevered beta from observed | C22: =C21/(1+(1-C19)*C14) -> 0.51609897 | E22: Reference only – local beta vs. SMI understates global systematic risk
B23: Selected unlevered beta (Assumptions) | C23: =Assumptions!$G$53 -> 0.8
B24: Relevered beta βu × (1 + (1 – t) × D/E) | C24: =C23*(1+(1-C19)*C14) -> 0.87502596
B26: Cost of equity (CAPM)
B27: Risk-free rate | C27: =Assumptions!$G$51 -> 0.01
B28: Equity risk premium | C28: =Assumptions!$G$52 -> 0.065
B29: Cost of equity rf + β × ERP | C29: =C27+C24*C28 -> 0.066876688
B31: Cost of debt
B32: Implied: 2025 interest expense / average debt | C32: =Historicals!$E$60/AVERAGE(Historicals!$D$111,Historicals!$E$111) -> 0.034303817 | E32: Cross-check for the Assumptions input
B33: Pre-tax cost of debt (Assumptions) | C33: =Assumptions!$G$54 -> 0.035
B34: After-tax cost of debt | C34: =C33*(1-C19) -> 0.02835
B36: Weighted average cost of capital
B37: WACC | C37: =C16*C29+C15*C34 -> 0.062878903

Sheet DCF
B1: DCF
B2: CHF millions. Mid-year convention with a stub period from the valuation date to 31 Dec 2026. | E2: ="Scenario: "&Assumptions!$E$4 -> Scenario: Base case
B4: Key inputs
B5: Valuation date | C5: =Assumptions!$D$7 -> 46267
B6: WACC | C6: =WACC!$C$37 -> 0.062878903
B7: Terminal growth | C7: =Assumptions!$G$48 -> 0.015
B8: Exit multiple (EV / EBITDA) | C8: =Assumptions!$G$49 -> 12
B9: Current share price | C9: =Assumptions!$D$8 -> 357
D12: 2026E | E12: 2027E | F12: 2028E | G12: 2029E | H12: 2030E
B13: Period end | D13: =DATE(YEAR($C$5),12,31) -> 46387 | E13: =DATE(YEAR(D13)+1,12,31) -> 46752 | F13: =DATE(YEAR(E13)+1,12,31) -> 47118 | G13: =DATE(YEAR(F13)+1,12,31) -> 47483 | H13: =DATE(YEAR(G13)+1,12,31) -> 47848
B14: Fraction of period after valuation date | D14: =MIN(1,(D13-$C$5)/(D13-DATE(YEAR(D13)-1,12,31))) -> 0.32876712 | E14: =MIN(1,(E13-$C$5)/(E13-DATE(YEAR(E13)-1,12,31))) -> 1 | F14: =MIN(1,(F13-$C$5)/(F13-DATE(YEAR(F13)-1,12,31))) -> 1 | G14: =MIN(1,(G13-$C$5)/(G13-DATE(YEAR(G13)-1,12,31))) -> 1 | H14: =MIN(1,(H13-$C$5)/(H13-DATE(YEAR(H13)-1,12,31))) -> 1
B15: Discount period (mid-year) | D15: =SUM($D$14:D14)-D14/2 -> 0.16438356 | E15: =SUM($D$14:E14)-E14/2 -> 0.82876712 | F15: =SUM($D$14:F14)-F14/2 -> 1.8287671 | G15: =SUM($D$14:G14)-G14/2 -> 2.8287671 | H15: =SUM($D$14:H14)-H14/2 -> 3.8287671
B16: Adjusted EBITDA | D16: ='Operating Model'!$D$29 -> 25691.437 | E16: ='Operating Model'!$E$29 -> 27035.516 | F16: ='Operating Model'!$F$29 -> 28371.125 | G16: ='Operating Model'!$G$29 -> 29510.935 | H16: ='Operating Model'!$H$29 -> 30579.753
B17: Unlevered free cash flow (full year) | D17: ='Operating Model'!$D$50 -> 15153.39 | E17: ='Operating Model'!$E$50 -> 16201.578 | F17: ='Operating Model'!$F$50 -> 17100.524 | G17: ='Operating Model'!$G$50 -> 17874.764 | H17: ='Operating Model'!$H$50 -> 18612.143
B18: UFCF attributable to valuation period | D18: =D17*D14 -> 4981.9366 | E18: =E17*E14 -> 16201.578 | F18: =F17*F14 -> 17100.524 | G18: =G17*G14 -> 17874.764 | H18: =H17*H14 -> 18612.143
B19: Discount factor | D19: =1/(1+$C$6)^D15 -> 0.99002577 | E19: =1/(1+$C$6)^E15 -> 0.95071667 | F19: =1/(1+$C$6)^F15 -> 0.89447318 | G19: =1/(1+$C$6)^G15 -> 0.84155699 | H19: =1/(1+$C$6)^H15 -> 0.79177128
B20: PV of UFCF | D20: =D18*D19 -> 4932.2456 | E20: =E18*E19 -> 15403.11 | F20: =F18*F19 -> 15295.96 | G20: =G18*G19 -> 15042.633 | H20: =H18*H19 -> 14736.56
B22: Terminal value & enterprise value
C23: Perpetuity | D23: Exit multiple
B24: Sum of PV of forecast UFCF | C24: =SUM($D$20:$H$20) -> 65410.509 | D24: =SUM($D$20:$H$20) -> 65410.509
B25: Terminal-year metric (2030E UFCF / EBITDA) | C25: =$H$17 -> 18612.143 | D25: =$H$16 -> 30579.753
B26: Terminal value at end-2030 | C26: =C25*(1+$C$7)/($C$6-$C$7) -> 394564.7 | D26: =D25*$C$8 -> 366957.04
B27: Discount period for TV | C27: =$H$15 -> 3.8287671 | D27: =SUM($D$14:$H$14) -> 4.3287671 | J27: Perpetuity: mid-year (cash flows continue mid-year); exit: year-end (sale at 31 Dec 2030)
B28: PV of terminal value | C28: =C26/(1+$C$6)^C27 -> 312405 | D28: =D26/(1+$C$6)^D27 -> 281820.82
B29: Enterprise value | C29: =C24+C28 -> 377815.51 | D29: =D24+D28 -> 347231.33
B30: Terminal value – % of EV | C30: =C28/C29 -> 0.82687183 | D30: =D28/D29 -> 0.81162267
B31: Implied exit multiple / implied perpetuity growth | C31: =C26/$H$16 -> 12.902808 | D31: =($C$6*D26-$H$17)/(D26+$H$17) -> 0.011571758
B32: EV / 2026E adjusted EBITDA | C32: =C29/$D$16 -> 14.705893 | D32: =D29/$D$16 -> 13.51545
B34: Enterprise value to equity value bridge
C35: Perpetuity | D35: Exit multiple
B36: Enterprise value | C36: =C29 -> 377815.51 | D36: =D29 -> 347231.33
B37: Less: total debt | C37: =-Historicals!$E$111 -> -31636 | D37: =-Historicals!$E$111 -> -31636 | J37: 31 Dec 2025 balance sheet
B38: Less: lease liabilities | C38: =-Historicals!$E$110 -> -1555 | D38: =-Historicals!$E$110 -> -1555 | J38: EBITDA is pre-lease, so leases are debt-like
B39: Plus: cash and cash equivalents | C39: =Historicals!$E$85 -> 5582 | D39: =Historicals!$E$85 -> 5582
B40: Plus: marketable securities | C40: =Historicals!$E$84 -> 9894 | D40: =Historicals!$E$84 -> 9894
B41: Less: net pension deficit | C41: =-Historicals!$E$117 -> -2159 | D41: =-Historicals!$E$117 -> -2159 | J41: DB liabilities less DB assets (pre-tax)
B42: Less: non-controlling interests (book) | C42: =-Historicals!$E$104 -> -4078 | D42: =-Historicals!$E$104 -> -4078 | J42: Mainly Chugai (Roche owns 61.1%); book value – see notes
B43: Total EV-to-equity adjustments | C43: =SUM(C37:C42) -> -23952 | D43: =SUM(D37:D42) -> -23952
B44: Equity value | C44: =C36+C43 -> 353863.51 | D44: =D36+D43 -> 323279.33
B45: Diluted shares (m) | C45: =Historicals!$E$30 -> 803 | D45: =Historicals!$E$30 -> 803
...

Sheet Sensitivity
B1: Sensitivity
B2: Implied value per share (CHF). Every cell is a live re-computation of the DCF at the given WACC and terminal assumption.
B4: WACC vs. terminal growth – perpetuity growth method
C5: Terminal growth →
B6: WACC ↓ | C6: =Assumptions!$G$48+(0-4)*Assumptions!$D$15 -> 0.005 | D6: =Assumptions!$G$48+(1-4)*Assumptions!$D$15 -> 0.0075 | E6: =Assumptions!$G$48+(2-4)*Assumptions!$D$15 -> 0.01 | F6: =Assumptions!$G$48+(3-4)*Assumptions!$D$15 -> 0.0125 | G6: =Assumptions!$G$48+(4-4)*Assumptions!$D$15 -> 0.015 | H6: =Assumptions!$G$48+(5-4)*Assumptions!$D$15 -> 0.0175 | I6: =Assumptions!$G$48+(6-4)*Assumptions!$D$15 -> 0.02 | J6: =Assumptions!$G$48+(7-4)*Assumptions!$D$15 -> 0.0225 | K6: =Assumptions!$G$48+(8-4)*Assumptions!$D$15 -> 0.025
B7: =WACC!$C$37+(0-4)*Assumptions!$D$14 -> 0.052878903 | C7: =(SUMPRODUCT(DCF!$D$18:$H$18/(1+$B7)^DCF!$D$15:$H$15)+DCF!$H$17*(1+C$6)/($B7-C$6)/(1+$B7)^DCF!$H$15+DCF!$C$43)/DCF!$C$45 -> 452.718 | D7: =(SUMPRODUCT(DCF!$D$18:$H$18/(1+$B7)^DCF!$D$15:$H$15)+DCF!$H$17*(1+D$6)/($B7-D$6)/(1+$B7)^DCF!$H$15+DCF!$C$43)/DCF!$C$45 -> 475.77057 | E7: =(SUMPRODUCT(DCF!$D$18:$H$18/(1+$B7)^DCF!$D$15:$H$15)+DCF!$H$17*(1+E$6)/($B7-E$6)/(1+$B7)^DCF!$H$15+DCF!$C$43)/DCF!$C$45 -> 501.51123 | F7: =(SUMPRODUCT(DCF!$D$18:$H$18/(1+$B7)^DCF!$D$15:$H$15)+DCF!$H$17*(1+F$6)/($B7-F$6)/(1+$B7)^DCF!$H$15+DCF!$C$43)/DCF!$C$45 -> 530.43929 | G7: =(SUMPRODUCT(DCF!$D$18:$H$18/(1+$B7)^DCF!$D$15:$H$15)+DCF!$H$17*(1+G$6)/($B7-G$6)/(1+$B7)^DCF!$H$15+DCF!$C$43)/DCF!$C$45 -> 563.18585 | H7: =(SUMPRODUCT(DCF!$D$18:$H$18/(1+$B7)^DCF!$D$15:$H$15)+DCF!$H$17*(1+H$6)/($B7-H$6)/(1+$B7)^DCF!$H$15+DCF!$C$43)/DCF!$C$45 -> 600.56037 | I7: =(SUMPRODUCT(DCF!$D$18:$H$18/(1+$B7)^DCF!$D$15:$H$15)+DCF!$H$17*(1+I$6)/($B7-I$6)/(1+$B7)^DCF!$H$15+DCF!$C$43)/DCF!$C$45 -> 643.61857 | J7: =(SUMPRODUCT(DCF!$D$18:$H$18/(1+$B7)^DCF!$D$15:$H$15)+DCF!$H$17*(1+J$6)/($B7-J$6)/(1+$B7)^DCF!$H$15+DCF!$C$43)/DCF!$C$45 -> 693.76362 | K7: =(SUMPRODUCT(DCF!$D$18:$H$18/(1+$B7)^DCF!$D$15:$H$15)+DCF!$H$17*(1+K$6)/($B7-K$6)/(1+$B7)^DCF!$H$15+DCF!$C$43)/DCF!$C$45 -> 752.90204
B8: =WACC!$C$37+(1-4)*Assumptions!$D$14 -> 0.055378903 | C8: =(SUMPRODUCT(DCF!$D$18:$H$18/(1+$B8)^DCF!$D$15:$H$15)+DCF!$H$17*(1+C$6)/($B8-C$6)/(1+$B8)^DCF!$H$15+DCF!$C$43)/DCF!$C$45 -> 429.04148 | D8: =(SUMPRODUCT(DCF!$D$18:$H$18/(1+$B8)^DCF!$D$15:$H$15)+DCF!$H$17*(1+D$6)/($B8-D$6)/(1+$B8)^DCF!$H$15+DCF!$C$43)/DCF!$C$45 -> 449.66729 | E8: =(SUMPRODUCT(DCF!$D$18:$H$18/(1+$B8)^DCF!$D$15:$H$15)+DCF!$H$17*(1+E$6)/($B8-E$6)/(1+$B8)^DCF!$H$15+DCF!$C$43)/DCF!$C$45 -> 472.56572 | F8: =(SUMPRODUCT(DCF!$D$18:$H$18/(1+$B8)^DCF!$D$15:$H$15)+DCF!$H$17*(1+F$6)/($B8-F$6)/(1+$B8)^DCF!$H$15+DCF!$C$43)/DCF!$C$45 -> 498.13427 | G8: =(SUMPRODUCT(DCF!$D$18:$H$18/(1+$B8)^DCF!$D$15:$H$15)+DCF!$H$17*(1+G$6)/($B8-G$6)/(1+$B8)^DCF!$H$15+DCF!$C$43)/DCF!$C$45 -> 526.86891 | H8: =(SUMPRODUCT(DCF!$D$18:$H$18/(1+$B8)^DCF!$D$15:$H$15)+DCF!$H$17*(1+H$6)/($B8-H$6)/(1+$B8)^DCF!$H$15+DCF!$C$43)/DCF!$C$45 -> 559.39651 | I8: =(SUMPRODUCT(DCF!$D$18:$H$18/(1+$B8)^DCF!$D$15:$H$15)+DCF!$H$17*(1+I$6)/($B8-I$6)/(1+$B8)^DCF!$H$15+DCF!$C$43)/DCF!$C$45 -> 596.52114 | J8: =(SUMPRODUCT(DCF!$D$18:$H$18/(1+$B8)^DCF!$D$15:$H$15)+DCF!$H$17*(1+J$6)/($B8-J$6)/(1+$B8)^DCF!$H$15+DCF!$C$43)/DCF!$C$45 -> 639.29143 | K8: =(SUMPRODUCT(DCF!$D$18:$H$18/(1+$B8)^DCF!$D$15:$H$15)+DCF!$H$17*(1+K$6)/($B8-K$6)/(1+$B8)^DCF!$H$15+DCF!$C$43)/DCF!$C$45 -> 689.1012
B9: =WACC!$C$37+(2-4)*Assumptions!$D$14 -> 0.057878903 | C9: =(SUMPRODUCT(DCF!$D$18:$H$18/(1+$B9)^DCF!$D$15:$H$15)+DCF!$H$17*(1+C$6)/($B9-C$6)/(1+$B9)^DCF!$H$15+DCF!$C$43)/DCF!$C$45 -> 407.60456 | D9: =(SUMPRODUCT(DCF!$D$18:$H$18/(1+$B9)^DCF!$D$15:$H$15)+DCF!$H$17*(1+D$6)/($B9-D$6)/(1+$B9)^DCF!$H$15+DCF!$C$43)/DCF!$C$45 -> 426.1555 | E9: =(SUMPRODUCT(DCF!$D$18:$H$18/(1+$B9)^DCF!$D$15:$H$15)+DCF!$H$17*(1+E$6)/($B9-E$6)/(1+$B9)^DCF!$H$15+DCF!$C$43)/DCF!$C$45 -> 446.64373 | F9: =(SUMPRODUCT(DCF!$D$18:$H$18/(1+$B9)^DCF!$D$15:$H$15)+DCF!$H$17*(1+F$6)/($B9-F$6)/(1+$B9)^DCF!$H$15+DCF!$C$43)/DCF!$C$45 -> 469.38941 | G9: =(SUMPRODUCT(DCF!$D$18:$H$18/(1+$B9)^DCF!$D$15:$H$15)+DCF!$H$17*(1+G$6)/($B9-G$6)/(1+$B9)^DCF!$H$15+DCF!$C$43)/DCF!$C$45 -> 494.78741 | H9: =(SUMPRODUCT(DCF!$D$18:$H$18/(1+$B9)^DCF!$D$15:$H$15)+DCF!$H$17*(1+H$6)/($B9-H$6)/(1+$B9)^DCF!$H$15+DCF!$C$43)/DCF!$C$45 -> 523.33037 | I9: =(SUMPRODUCT(DCF!$D$18:$H$18/(1+$B9)^DCF!$D$15:$H$15)+DCF!$H$17*(1+I$6)/($B9-I$6)/(1+$B9)^DCF!$H$15+DCF!$C$43)/DCF!$C$45 -> 555.64099 | J9: =(SUMPRODUCT(DCF!$D$18:$H$18/(1+$B9)^DCF!$D$15:$H$15)+DCF!$H$17*(1+J$6)/($B9-J$6)/(1+$B9)^DCF!$H$15+DCF!$C$43)/DCF!$C$45 -> 592.51798 | K9: =(SUMPRODUCT(DCF!$D$18:$H$18/(1+$B9)^DCF!$D$15:$H$15)+DCF!$H$17*(1+K$6)/($B9-K$6)/(1+$B9)^DCF!$H$15+DCF!$C$43)/DCF!$C$45 -> 635.00297
B10: =WACC!$C$37+(3-4)*Assumptions!$D$14 -> 0.060378903 | C10: =(SUMPRODUCT(DCF!$D$18:$H$18/(1+$B10)^DCF!$D$15:$H$15)+DCF!$H$17*(1+C$6)/($B10-C$6)/(1+$B10)^DCF!$H$15+DCF!$C$43)/DCF!$C$45 -> 388.10392 | D10: =(SUMPRODUCT(DCF!$D$18:$H$18/(1+$B10)^DCF!$D$15:$H$15)+DCF!$H$17*(1+D$6)/($B10-D$6)/(1+$B10)^DCF!$H$15+DCF!$C$43)/DCF!$C$45 -> 404.86764 | E10: =(SUMPRODUCT(DCF!$D$18:$H$18/(1+$B10)^DCF!$D$15:$H$15)+DCF!$H$17*(1+E$6)/($B10-E$6)/(1+$B10)^DCF!$H$15+DCF!$C$43)/DCF!$C$45 -> 423.29514 | F10: =(SUMPRODUCT(DCF!$D$18:$H$18/(1+$B10)^DCF!$D$15:$H$15)+DCF!$H$17*(1+F$6)/($B10-F$6)/(1+$B10)^DCF!$H$15+DCF!$C$43)/DCF!$C$45 -> 443.64701 | G10: =(SUMPRODUCT(DCF!$D$18:$H$18/(1+$B10)^DCF!$D$15:$H$15)+DCF!$H$17*(1+G$6)/($B10-G$6)/(1+$B10)^DCF!$H$15+DCF!$C$43)/DCF!$C$45 -> 466.24133 | H10: =(SUMPRODUCT(DCF!$D$18:$H$18/(1+$B10)^DCF!$D$15:$H$15)+DCF!$H$17*(1+H$6)/($B10-H$6)/(1+$B10)^DCF!$H$15+DCF!$C$43)/DCF!$C$45 -> 491.47031 | I10: =(SUMPRODUCT(DCF!$D$18:$H$18/(1+$B10)^DCF!$D$15:$H$15)+DCF!$H$17*(1+I$6)/($B10-I$6)/(1+$B10)^DCF!$H$15+DCF!$C$43)/DCF!$C$45 -> 519.82332 | J10: =(SUMPRODUCT(DCF!$D$18:$H$18/(1+$B10)^DCF!$D$15:$H$15)+DCF!$H$17*(1+J$6)/($B10-J$6)/(1+$B10)^DCF!$H$15+DCF!$C$43)/DCF!$C$45 -> 551.91892 | K10: =(SUMPRODUCT(DCF!$D$18:$H$18/(1+$B10)^DCF!$D$15:$H$15)+DCF!$H$17*(1+K$6)/($B10-K$6)/(1+$B10)^DCF!$H$15+DCF!$C$43)/DCF!$C$45 -> 588.5505
B11: =WACC!$C$37+(4-4)*Assumptions!$D$14 -> 0.062878903 | C11: =(SUMPRODUCT(DCF!$D$18:$H$18/(1+$B11)^DCF!$D$15:$H$15)+DCF!$H$17*(1+C$6)/($B11-C$6)/(1+$B11)^DCF!$H$15+DCF!$C$43)/DCF!$C$45 -> 370.28864 | D11: =(SUMPRODUCT(DCF!$D$18:$H$18/(1+$B11)^DCF!$D$15:$H$15)+DCF!$H$17*(1+D$6)/($B11-D$6)/(1+$B11)^DCF!$H$15+DCF!$C$43)/DCF!$C$45 -> 385.50251 | E11: =(SUMPRODUCT(DCF!$D$18:$H$18/(1+$B11)^DCF!$D$15:$H$15)+DCF!$H$17*(1+E$6)/($B11-E$6)/(1+$B11)^DCF!$H$15+DCF!$C$43)/DCF!$C$45 -> 402.15494 | F11: =(SUMPRODUCT(DCF!$D$18:$H$18/(1+$B11)^DCF!$D$15:$H$15)+DCF!$H$17*(1+F$6)/($B11-F$6)/(1+$B11)^DCF!$H$15+DCF!$C$43)/DCF!$C$45 -> 420.46009 | G11: =(SUMPRODUCT(DCF!$D$18:$H$18/(1+$B11)^DCF!$D$15:$H$15)+DCF!$H$17*(1+G$6)/($B11-G$6)/(1+$B11)^DCF!$H$15+DCF!$C$43)/DCF!$C$45 -> 440.67685 | H11: =(SUMPRODUCT(DCF!$D$18:$H$18/(1+$B11)^DCF!$D$15:$H$15)+DCF!$H$17*(1+H$6)/($B11-H$6)/(1+$B11)^DCF!$H$15+DCF!$C$43)/DCF!$C$45 -> 463.12115 | I11: =(SUMPRODUCT(DCF!$D$18:$H$18/(1+$B11)^DCF!$D$15:$H$15)+DCF!$H$17*(1+I$6)/($B11-I$6)/(1+$B11)^DCF!$H$15+DCF!$C$43)/DCF!$C$45 -> 488.18263 | J11: =(SUMPRODUCT(DCF!$D$18:$H$18/(1+$B11)^DCF!$D$15:$H$15)+DCF!$H$17*(1+J$6)/($B11-J$6)/(1+$B11)^DCF!$H$15+DCF!$C$43)/DCF!$C$45 -> 516.3474 | K11: =(SUMPRODUCT(DCF!$D$18:$H$18/(1+$B11)^DCF!$D$15:$H$15)+DCF!$H$17*(1+K$6)/($B11-K$6)/(1+$B11)^DCF!$H$15+DCF!$C$43)/DCF!$C$45 -> 548.22991
B12: =WACC!$C$37+(5-4)*Assumptions!$D$14 -> 0.065378903 | C12: =(SUMPRODUCT(DCF!$D$18:$H$18/(1+$B12)^DCF!$D$15:$H$15)+DCF!$H$17*(1+C$6)/($B12-C$6)/(1+$B12)^DCF!$H$15+DCF!$C$43)/DCF!$C$45 -> 353.94937 | D12: =(SUMPRODUCT(DCF!$D$18:$H$18/(1+$B12)^DCF!$D$15:$H$15)+DCF!$H$17*(1+D$6)/($B12-D$6)/(1+$B12)^DCF!$H$15+DCF!$C$43)/DCF!$C$45 -> 367.81095 | E12: =(SUMPRODUCT(DCF!$D$18:$H$18/(1+$B12)^DCF!$D$15:$H$15)+DCF!$H$17*(1+E$6)/($B12-E$6)/(1+$B12)^DCF!$H$15+DCF!$C$43)/DCF!$C$45 -> 382.92405 | F12: =(SUMPRODUCT(DCF!$D$18:$H$18/(1+$B12)^DCF!$D$15:$H$15)+DCF!$H$17*(1+F$6)/($B12-F$6)/(1+$B12)^DCF!$H$15+DCF!$C$43)/DCF!$C$45 -> 399.46618 | G12: =(SUMPRODUCT(DCF!$D$18:$H$18/(1+$B12)^DCF!$D$15:$H$15)+DCF!$H$17*(1+G$6)/($B12-G$6)/(1+$B12)^DCF!$H$15+DCF!$C$43)/DCF!$C$45 -> 417.65008 | H12: =(SUMPRODUCT(DCF!$D$18:$H$18/(1+$B12)^DCF!$D$15:$H$15)+DCF!$H$17*(1+H$6)/($B12-H$6)/(1+$B12)^DCF!$H$15+DCF!$C$43)/DCF!$C$45 -> 437.73292 | I12: =(SUMPRODUCT(DCF!$D$18:$H$18/(1+$B12)^DCF!$D$15:$H$15)+DCF!$H$17*(1+I$6)/($B12-I$6)/(1+$B12)^DCF!$H$15+DCF!$C$43)/DCF!$C$45 -> 460.02857 | J12: =(SUMPRODUCT(DCF!$D$18:$H$18/(1+$B12)^DCF!$D$15:$H$15)+DCF!$H$17*(1+J$6)/($B12-J$6)/(1+$B12)^DCF!$H$15+DCF!$C$43)/DCF!$C$45 -> 484.92405 | K12: =(SUMPRODUCT(DCF!$D$18:$H$18/(1+$B12)^DCF!$D$15:$H$15)+DCF!$H$17*(1+K$6)/($B12-K$6)/(1+$B12)^DCF!$H$15+DCF!$C$43)/DCF!$C$45 -> 512.90226
B13: =WACC!$C$37+(6-4)*Assumptions!$D$14 -> 0.067878903 | C13: =(SUMPRODUCT(DCF!$D$18:$H$18/(1+$B13)^DCF!$D$15:$H$15)+DCF!$H$17*(1+C$6)/($B13-C$6)/(1+$B13)^DCF!$H$15+DCF!$C$43)/DCF!$C$45 -> 338.91005 | D13: =(SUMPRODUCT(DCF!$D$18:$H$18/(1+$B13)^DCF!$D$15:$H$15)+DCF!$H$17*(1+D$6)/($B13-D$6)/(1+$B13)^DCF!$H$15+DCF!$C$43)/DCF!$C$45 -> 351.58507 | E13: =(SUMPRODUCT(DCF!$D$18:$H$18/(1+$B13)^DCF!$D$15:$H$15)+DCF!$H$17*(1+E$6)/($B13-E$6)/(1+$B13)^DCF!$H$15+DCF!$C$43)/DCF!$C$45 -> 365.35504 | F13: =(SUMPRODUCT(DCF!$D$18:$H$18/(1+$B13)^DCF!$D$15:$H$15)+DCF!$H$17*(1+F$6)/($B13-F$6)/(1+$B13)^DCF!$H$15+DCF!$C$43)/DCF!$C$45 -> 380.36827 | G13: =(SUMPRODUCT(DCF!$D$18:$H$18/(1+$B13)^DCF!$D$15:$H$15)+DCF!$H$17*(1+G$6)/($B13-G$6)/(1+$B13)^DCF!$H$15+DCF!$C$43)/DCF!$C$45 -> 396.80108 | H13: =(SUMPRODUCT(DCF!$D$18:$H$18/(1+$B13)^DCF!$D$15:$H$15)+DCF!$H$17*(1+H$6)/($B13-H$6)/(1+$B13)^DCF!$H$15+DCF!$C$43)/DCF!$C$45 -> 414.86482 | I13: =(SUMPRODUCT(DCF!$D$18:$H$18/(1+$B13)^DCF!$D$15:$H$15)+DCF!$H$17*(1+I$6)/($B13-I$6)/(1+$B13)^DCF!$H$15+DCF!$C$43)/DCF!$C$45 -> 434.81495 | J13: =(SUMPRODUCT(DCF!$D$18:$H$18/(1+$B13)^DCF!$D$15:$H$15)+DCF!$H$17*(1+J$6)/($B13-J$6)/(1+$B13)^DCF!$H$15+DCF!$C$43)/DCF!$C$45 -> 456.96326 | K13: =(SUMPRODUCT(DCF!$D$18:$H$18/(1+$B13)^DCF!$D$15:$H$15)+DCF!$H$17*(1+K$6)/($B13-K$6)/(1+$B13)^DCF!$H$15+DCF!$C$43)/DCF!$C$45 -> 481.69423
B14: =WACC!$C$37+(7-4)*Assumptions!$D$14 -> 0.070378903 | C14: =(SUMPRODUCT(DCF!$D$18:$H$18/(1+$B14)^DCF!$D$15:$H$15)+DCF!$H$17*(1+C$6)/($B14-C$6)/(1+$B14)^DCF!$H$15+DCF!$C$43)/DCF!$C$45 -> 325.02153 | D14: =(SUMPRODUCT(DCF!$D$18:$H$18/(1+$B14)^DCF!$D$15:$H$15)+DCF!$H$17*(1+D$6)/($B14-D$6)/(1+$B14)^DCF!$H$15+DCF!$C$43)/DCF!$C$45 -> 336.65003 | E14: =(SUMPRODUCT(DCF!$D$18:$H$18/(1+$B14)^DCF!$D$15:$H$15)+DCF!$H$17*(1+E$6)/($B14-E$6)/(1+$B14)^DCF!$H$15+DCF!$C$43)/DCF!$C$45 -> 349.24148 | F14: =(SUMPRODUCT(DCF!$D$18:$H$18/(1+$B14)^DCF!$D$15:$H$15)+DCF!$H$17*(1+F$6)/($B14-F$6)/(1+$B14)^DCF!$H$15+DCF!$C$43)/DCF!$C$45 -> 362.92067 | G14: =(SUMPRODUCT(DCF!$D$18:$H$18/(1+$B14)^DCF!$D$15:$H$15)+DCF!$H$17*(1+G$6)/($B14-G$6)/(1+$B14)^DCF!$H$15+DCF!$C$43)/DCF!$C$45 -> 377.83492 | H14: =(SUMPRODUCT(DCF!$D$18:$H$18/(1+$B14)^DCF!$D$15:$H$15)+DCF!$H$17*(1+H$6)/($B14-H$6)/(1+$B14)^DCF!$H$15+DCF!$C$43)/DCF!$C$45 -> 394.1594 | I14: =(SUMPRODUCT(DCF!$D$18:$H$18/(1+$B14)^DCF!$D$15:$H$15)+DCF!$H$17*(1+I$6)/($B14-I$6)/(1+$B14)^DCF!$H$15+DCF!$C$43)/DCF!$C$45 -> 412.10404 | J14: =(SUMPRODUCT(DCF!$D$18:$H$18/(1+$B14)^DCF!$D$15:$H$15)+DCF!$H$17*(1+J$6)/($B14-J$6)/(1+$B14)^DCF!$H$15+DCF!$C$43)/DCF!$C$45 -> 431.92265 | K14: =(SUMPRODUCT(DCF!$D$18:$H$18/(1+$B14)^DCF!$D$15:$H$15)+DCF!$H$17*(1+K$6)/($B14-K$6)/(1+$B14)^DCF!$H$15+DCF!$C$43)/DCF!$C$45 -> 453.92494
B15: =WACC!$C$37+(8-4)*Assumptions!$D$14 -> 0.072878903 | C15: =(SUMPRODUCT(DCF!$D$18:$H$18/(1+$B15)^DCF!$D$15:$H$15)+DCF!$H$17*(1+C$6)/($B15-C$6)/(1+$B15)^DCF!$H$15+DCF!$C$43)/DCF!$C$45 -> 312.15667 | D15: =(SUMPRODUCT(DCF!$D$18:$H$18/(1+$B15)^DCF!$D$15:$H$15)+DCF!$H$17*(1+D$6)/($B15-D$6)/(1+$B15)^DCF!$H$15+DCF!$C$43)/DCF!$C$45 -> 322.85775 | E15: =(SUMPRODUCT(DCF!$D$18:$H$18/(1+$B15)^DCF!$D$15:$H$15)+DCF!$H$17*(1+E$6)/($B15-E$6)/(1+$B15)^DCF!$H$15+DCF!$C$43)/DCF!$C$45 -> 334.40975 | F15: =(SUMPRODUCT(DCF!$D$18:$H$18/(1+$B15)^DCF!$D$15:$H$15)+DCF!$H$17*(1+F$6)/($B15-F$6)/(1+$B15)^DCF!$H$15+DCF!$C$43)/DCF!$C$45 -> 346.91838 | G15: =(SUMPRODUCT(DCF!$D$18:$H$18/(1+$B15)^DCF!$D$15:$H$15)+DCF!$H$17*(1+G$6)/($B15-G$6)/(1+$B15)^DCF!$H$15+DCF!$C$43)/DCF!$C$45 -> 360.5076 | H15: =(SUMPRODUCT(DCF!$D$18:$H$18/(1+$B15)^DCF!$D$15:$H$15)+DCF!$H$17*(1+H$6)/($B15-H$6)/(1+$B15)^DCF!$H$15+DCF!$C$43)/DCF!$C$45 -> 375.32375 | I15: =(SUMPRODUCT(DCF!$D$18:$H$18/(1+$B15)^DCF!$D$15:$H$15)+DCF!$H$17*(1+I$6)/($B15-I$6)/(1+$B15)^DCF!$H$15+DCF!$C$43)/DCF!$C$45 -> 391.54085 | J15: =(SUMPRODUCT(DCF!$D$18:$H$18/(1+$B15)^DCF!$D$15:$H$15)+DCF!$H$17*(1+J$6)/($B15-J$6)/(1+$B15)^DCF!$H$15+DCF!$C$43)/DCF!$C$45 -> 409.36747 | K15: =(SUMPRODUCT(DCF!$D$18:$H$18/(1+$B15)^DCF!$D$15:$H$15)+DCF!$H$17*(1+K$6)/($B15-K$6)/(1+$B15)^DCF!$H$15+DCF!$C$43)/DCF!$C$45 -> 429.05572
B17: WACC vs. exit multiple – exit multiple method
C18: Exit EV / EBITDA multiple →
B19: WACC ↓ | C19: =Assumptions!$G$49+(0-4)*Assumptions!$D$16 -> 10 | D19: =Assumptions!$G$49+(1-4)*Assumptions!$D$16 -> 10.5 | E19: =Assumptions!$G$49+(2-4)*Assumptions!$D$16 -> 11 | F19: =Assumptions!$G$49+(3-4)*Assumptions!$D$16 -> 11.5 | G19: =Assumptions!$G$49+(4-4)*Assumptions!$D$16 -> 12 | H19: =Assumptions!$G$49+(5-4)*Assumptions!$D$16 -> 12.5 | I19: =Assumptions!$G$49+(6-4)*Assumptions!$D$16 -> 13 | J19: =Assumptions!$G$49+(7-4)*Assumptions!$D$16 -> 13.5 | K19: =Assumptions!$G$49+(8-4)*Assumptions!$D$16 -> 14
B20: =WACC!$C$37+(0-4)*Assumptions!$D$14 -> 0.052878903 | C20: =(SUMPRODUCT(DCF!$D$18:$H$18/(1+$B20)^DCF!$D$15:$H$15)+DCF!$H$16*C$19/(1+$B20)^DCF!$D$27+DCF!$C$43)/DCF!$C$45 -> 357.98862 | D20: =(SUMPRODUCT(DCF!$D$18:$H$18/(1+$B20)^DCF!$D$15:$H$15)+DCF!$H$16*D$19/(1+$B20)^DCF!$D$27+DCF!$C$43)/DCF!$C$45 -> 373.22274 | E20: =(SUMPRODUCT(DCF!$D$18:$H$18/(1+$B20)^DCF!$D$15:$H$15)+DCF!$H$16*E$19/(1+$B20)^DCF!$D$27+DCF!$C$43)/DCF!$C$45 -> 388.45686 | F20: =(SUMPRODUCT(DCF!$D$18:$H$18/(1+$B20)^DCF!$D$15:$H$15)+DCF!$H$16*F$19/(1+$B20)^DCF!$D$27+DCF!$C$43)/DCF!$C$45 -> 403.69099 | G20: =(SUMPRODUCT(DCF!$D$18:$H$18/(1+$B20)^DCF!$D$15:$H$15)+DCF!$H$16*G$19/(1+$B20)^DCF!$D$27+DCF!$C$43)/DCF!$C$45 -> 418.92511 | H20: =(SUMPRODUCT(DCF!$D$18:$H$18/(1+$B20)^DCF!$D$15:$H$15)+DCF!$H$16*H$19/(1+$B20)^DCF!$D$27+DCF!$C$43)/DCF!$C$45 -> 434.15923 | I20: =(SUMPRODUCT(DCF!$D$18:$H$18/(1+$B20)^DCF!$D$15:$H$15)+DCF!$H$16*I$19/(1+$B20)^DCF!$D$27+DCF!$C$43)/DCF!$C$45 -> 449.39335 | J20: =(SUMPRODUCT(DCF!$D$18:$H$18/(1+$B20)^DCF!$D$15:$H$15)+DCF!$H$16*J$19/(1+$B20)^DCF!$D$27+DCF!$C$43)/DCF!$C$45 -> 464.62748 | K20: =(SUMPRODUCT(DCF!$D$18:$H$18/(1+$B20)^DCF!$D$15:$H$15)+DCF!$H$16*K$19/(1+$B20)^DCF!$D$27+DCF!$C$43)/DCF!$C$45 -> 479.8616
B21: =WACC!$C$37+(1-4)*Assumptions!$D$14 -> 0.055378903 | C21: =(SUMPRODUCT(DCF!$D$18:$H$18/(1+$B21)^DCF!$D$15:$H$15)+DCF!$H$16*C$19/(1+$B21)^DCF!$D$27+DCF!$C$43)/DCF!$C$45 -> 354.45179 | D21: =(SUMPRODUCT(DCF!$D$18:$H$18/(1+$B21)^DCF!$D$15:$H$15)+DCF!$H$16*D$19/(1+$B21)^DCF!$D$27+DCF!$C$43)/DCF!$C$45 -> 369.53032 | E21: =(SUMPRODUCT(DCF!$D$18:$H$18/(1+$B21)^DCF!$D$15:$H$15)+DCF!$H$16*E$19/(1+$B21)^DCF!$D$27+DCF!$C$43)/DCF!$C$45 -> 384.60885 | F21: =(SUMPRODUCT(DCF!$D$18:$H$18/(1+$B21)^DCF!$D$15:$H$15)+DCF!$H$16*F$19/(1+$B21)^DCF!$D$27+DCF!$C$43)/DCF!$C$45 -> 399.68737 | G21: =(SUMPRODUCT(DCF!$D$18:$H$18/(1+$B21)^DCF!$D$15:$H$15)+DCF!$H$16*G$19/(1+$B21)^DCF!$D$27+DCF!$C$43)/DCF!$C$45 -> 414.7659 | H21: =(SUMPRODUCT(DCF!$D$18:$H$18/(1+$B21)^DCF!$D$15:$H$15)+DCF!$H$16*H$19/(1+$B21)^DCF!$D$27+DCF!$C$43)/DCF!$C$45 -> 429.84442 | I21: =(SUMPRODUCT(DCF!$D$18:$H$18/(1+$B21)^DCF!$D$15:$H$15)+DCF!$H$16*I$19/(1+$B21)^DCF!$D$27+DCF!$C$43)/DCF!$C$45 -> 444.92295 | J21: =(SUMPRODUCT(DCF!$D$18:$H$18/(1+$B21)^DCF!$D$15:$H$15)+DCF!$H$16*J$19/(1+$B21)^DCF!$D$27+DCF!$C$43)/DCF!$C$45 -> 460.00148 | K21: =(SUMPRODUCT(DCF!$D$18:$H$18/(1+$B21)^DCF!$D$15:$H$15)+DCF!$H$16*K$19/(1+$B21)^DCF!$D$27+DCF!$C$43)/DCF!$C$45 -> 475.08
B22: =WACC!$C$37+(2-4)*Assumptions!$D$14 -> 0.057878903 | C22: =(SUMPRODUCT(DCF!$D$18:$H$18/(1+$B22)^DCF!$D$15:$H$15)+DCF!$H$16*C$19/(1+$B22)^DCF!$D$27+DCF!$C$43)/DCF!$C$45 -> 350.95785 | D22: =(SUMPRODUCT(DCF!$D$18:$H$18/(1+$B22)^DCF!$D$15:$H$15)+DCF!$H$16*D$19/(1+$B22)^DCF!$D$27+DCF!$C$43)/DCF!$C$45 -> 365.88274 | E22: =(SUMPRODUCT(DCF!$D$18:$H$18/(1+$B22)^DCF!$D$15:$H$15)+DCF!$H$16*E$19/(1+$B22)^DCF!$D$27+DCF!$C$43)/DCF!$C$45 -> 380.80762 | F22: =(SUMPRODUCT(DCF!$D$18:$H$18/(1+$B22)^DCF!$D$15:$H$15)+DCF!$H$16*F$19/(1+$B22)^DCF!$D$27+DCF!$C$43)/DCF!$C$45 -> 395.7325 | G22: =(SUMPRODUCT(DCF!$D$18:$H$18/(1+$B22)^DCF!$D$15:$H$15)+DCF!$H$16*G$19/(1+$B22)^DCF!$D$27+DCF!$C$43)/DCF!$C$45 -> 410.65738 | H22: =(SUMPRODUCT(DCF!$D$18:$H$18/(1+$B22)^DCF!$D$15:$H$15)+DCF!$H$16*H$19/(1+$B22)^DCF!$D$27+DCF!$C$43)/DCF!$C$45 -> 425.58226 | I22: =(SUMPRODUCT(DCF!$D$18:$H$18/(1+$B22)^DCF!$D$15:$H$15)+DCF!$H$16*I$19/(1+$B22)^DCF!$D$27+DCF!$C$43)/DCF!$C$45 -> 440.50714 | J22: =(SUMPRODUCT(DCF!$D$18:$H$18/(1+$B22)^DCF!$D$15:$H$15)+DCF!$H$16*J$19/(1+$B22)^DCF!$D$27+DCF!$C$43)/DCF!$C$45 -> 455.43202 | K22: =(SUMPRODUCT(DCF!$D$18:$H$18/(1+$B22)^DCF!$D$15:$H$15)+DCF!$H$16*K$19/(1+$B22)^DCF!$D$27+DCF!$C$43)/DCF!$C$45 -> 470.3569
B23: =WACC!$C$37+(3-4)*Assumptions!$D$14 -> 0.060378903 | C23: =(SUMPRODUCT(DCF!$D$18:$H$18/(1+$B23)^DCF!$D$15:$H$15)+DCF!$H$16*C$19/(1+$B23)^DCF!$D$27+DCF!$C$43)/DCF!$C$45 -> 347.50617 | D23: =(SUMPRODUCT(DCF!$D$18:$H$18/(1+$B23)^DCF!$D$15:$H$15)+DCF!$H$16*D$19/(1+$B23)^DCF!$D$27+DCF!$C$43)/DCF!$C$45 -> 362.27933 | E23: =(SUMPRODUCT(DCF!$D$18:$H$18/(1+$B23)^DCF!$D$15:$H$15)+DCF!$H$16*E$19/(1+$B23)^DCF!$D$27+DCF!$C$43)/DCF!$C$45 -> 377.05249 | F23: =(SUMPRODUCT(DCF!$D$18:$H$18/(1+$B23)^DCF!$D$15:$H$15)+DCF!$H$16*F$19/(1+$B23)^DCF!$D$27+DCF!$C$43)/DCF!$C$45 -> 391.82565 | G23: =(SUMPRODUCT(DCF!$D$18:$H$18/(1+$B23)^DCF!$D$15:$H$15)+DCF!$H$16*G$19/(1+$B23)^DCF!$D$27+DCF!$C$43)/DCF!$C$45 -> 406.59881 | H23: =(SUMPRODUCT(DCF!$D$18:$H$18/(1+$B23)^DCF!$D$15:$H$15)+DCF!$H$16*H$19/(1+$B23)^DCF!$D$27+DCF!$C$43)/DCF!$C$45 -> 421.37196 | I23: =(SUMPRODUCT(DCF!$D$18:$H$18/(1+$B23)^DCF!$D$15:$H$15)+DCF!$H$16*I$19/(1+$B23)^DCF!$D$27+DCF!$C$43)/DCF!$C$45 -> 436.14512 | J23: =(SUMPRODUCT(DCF!$D$18:$H$18/(1+$B23)^DCF!$D$15:$H$15)+DCF!$H$16*J$19/(1+$B23)^DCF!$D$27+DCF!$C$43)/DCF!$C$45 -> 450.91828 | K23: =(SUMPRODUCT(DCF!$D$18:$H$18/(1+$B23)^DCF!$D$15:$H$15)+DCF!$H$16*K$19/(1+$B23)^DCF!$D$27+DCF!$C$43)/DCF!$C$45 -> 465.69144
B24: =WACC!$C$37+(4-4)*Assumptions!$D$14 -> 0.062878903 | C24: =(SUMPRODUCT(DCF!$D$18:$H$18/(1+$B24)^DCF!$D$15:$H$15)+DCF!$H$16*C$19/(1+$B24)^DCF!$D$27+DCF!$C$43)/DCF!$C$45 -> 344.09613 | D24: =(SUMPRODUCT(DCF!$D$18:$H$18/(1+$B24)^DCF!$D$15:$H$15)+DCF!$H$16*D$19/(1+$B24)^DCF!$D$27+DCF!$C$43)/DCF!$C$45 -> 358.71946 | E24: =(SUMPRODUCT(DCF!$D$18:$H$18/(1+$B24)^DCF!$D$15:$H$15)+DCF!$H$16*E$19/(1+$B24)^DCF!$D$27+DCF!$C$43)/DCF!$C$45 -> 373.34279 | F24: =(SUMPRODUCT(DCF!$D$18:$H$18/(1+$B24)^DCF!$D$15:$H$15)+DCF!$H$16*F$19/(1+$B24)^DCF!$D$27+DCF!$C$43)/DCF!$C$45 -> 387.96612 | G24: =(SUMPRODUCT(DCF!$D$18:$H$18/(1+$B24)^DCF!$D$15:$H$15)+DCF!$H$16*G$19/(1+$B24)^DCF!$D$27+DCF!$C$43)/DCF!$C$45 -> 402.58945 | H24: =(SUMPRODUCT(DCF!$D$18:$H$18/(1+$B24)^DCF!$D$15:$H$15)+DCF!$H$16*H$19/(1+$B24)^DCF!$D$27+DCF!$C$43)/DCF!$C$45 -> 417.21278 | I24: =(SUMPRODUCT(DCF!$D$18:$H$18/(1+$B24)^DCF!$D$15:$H$15)+DCF!$H$16*I$19/(1+$B24)^DCF!$D$27+DCF!$C$43)/DCF!$C$45 -> 431.83611 | J24: =(SUMPRODUCT(DCF!$D$18:$H$18/(1+$B24)^DCF!$D$15:$H$15)+DCF!$H$16*J$19/(1+$B24)^DCF!$D$27+DCF!$C$43)/DCF!$C$45 -> 446.45944 | K24: =(SUMPRODUCT(DCF!$D$18:$H$18/(1+$B24)^DCF!$D$15:$H$15)+DCF!$H$16*K$19/(1+$B24)^DCF!$D$27+DCF!$C$43)/DCF!$C$45 -> 461.08277
B25: =WACC!$C$37+(5-4)*Assumptions!$D$14 -> 0.065378903 | C25: =(SUMPRODUCT(DCF!$D$18:$H$18/(1+$B25)^DCF!$D$15:$H$15)+DCF!$H$16*C$19/(1+$B25)^DCF!$D$27+DCF!$C$43)/DCF!$C$45 -> 340.72712 | D25: =(SUMPRODUCT(DCF!$D$18:$H$18/(1+$B25)^DCF!$D$15:$H$15)+DCF!$H$16*D$19/(1+$B25)^DCF!$D$27+DCF!$C$43)/DCF!$C$45 -> 355.20249 | E25: =(SUMPRODUCT(DCF!$D$18:$H$18/(1+$B25)^DCF!$D$15:$H$15)+DCF!$H$16*E$19/(1+$B25)^DCF!$D$27+DCF!$C$43)/DCF!$C$45 -> 369.67786 | F25: =(SUMPRODUCT(DCF!$D$18:$H$18/(1+$B25)^DCF!$D$15:$H$15)+DCF!$H$16*F$19/(1+$B25)^DCF!$D$27+DCF!$C$43)/DCF!$C$45 -> 384.15323 | G25: =(SUMPRODUCT(DCF!$D$18:$H$18/(1+$B25)^DCF!$D$15:$H$15)+DCF!$H$16*G$19/(1+$B25)^DCF!$D$27+DCF!$C$43)/DCF!$C$45 -> 398.6286 | H25: =(SUMPRODUCT(DCF!$D$18:$H$18/(1+$B25)^DCF!$D$15:$H$15)+DCF!$H$16*H$19/(1+$B25)^DCF!$D$27+DCF!$C$43)/DCF!$C$45 -> 413.10397 | I25: =(SUMPRODUCT(DCF!$D$18:$H$18/(1+$B25)^DCF!$D$15:$H$15)+DCF!$H$16*I$19/(1+$B25)^DCF!$D$27+DCF!$C$43)/DCF!$C$45 -> 427.57933 | J25: =(SUMPRODUCT(DCF!$D$18:$H$18/(1+$B25)^DCF!$D$15:$H$15)+DCF!$H$16*J$19/(1+$B25)^DCF!$D$27+DCF!$C$43)/DCF!$C$45 -> 442.0547 | K25: =(SUMPRODUCT(DCF!$D$18:$H$18/(1+$B25)^DCF!$D$15:$H$15)+DCF!$H$16*K$19/(1+$B25)^DCF!$D$27+DCF!$C$43)/DCF!$C$45 -> 456.53007
B26: =WACC!$C$37+(6-4)*Assumptions!$D$14 -> 0.067878903 | C26: =(SUMPRODUCT(DCF!$D$18:$H$18/(1+$B26)^DCF!$D$15:$H$15)+DCF!$H$16*C$19/(1+$B26)^DCF!$D$27+DCF!$C$43)/DCF!$C$45 -> 337.39856 | D26: =(SUMPRODUCT(DCF!$D$18:$H$18/(1+$B26)^DCF!$D$15:$H$15)+DCF!$H$16*D$19/(1+$B26)^DCF!$D$27+DCF!$C$43)/DCF!$C$45 -> 351.72781 | E26: =(SUMPRODUCT(DCF!$D$18:$H$18/(1+$B26)^DCF!$D$15:$H$15)+DCF!$H$16*E$19/(1+$B26)^DCF!$D$27+DCF!$C$43)/DCF!$C$45 -> 366.05705 | F26: =(SUMPRODUCT(DCF!$D$18:$H$18/(1+$B26)^DCF!$D$15:$H$15)+DCF!$H$16*F$19/(1+$B26)^DCF!$D$27+DCF!$C$43)/DCF!$C$45 -> 380.3863 | G26: =(SUMPRODUCT(DCF!$D$18:$H$18/(1+$B26)^DCF!$D$15:$H$15)+DCF!$H$16*G$19/(1+$B26)^DCF!$D$27+DCF!$C$43)/DCF!$C$45 -> 394.71554 | H26: =(SUMPRODUCT(DCF!$D$18:$H$18/(1+$B26)^DCF!$D$15:$H$15)+DCF!$H$16*H$19/(1+$B26)^DCF!$D$27+DCF!$C$43)/DCF!$C$45 -> 409.04479 | I26: =(SUMPRODUCT(DCF!$D$18:$H$18/(1+$B26)^DCF!$D$15:$H$15)+DCF!$H$16*I$19/(1+$B26)^DCF!$D$27+DCF!$C$43)/DCF!$C$45 -> 423.37403 | J26: =(SUMPRODUCT(DCF!$D$18:$H$18/(1+$B26)^DCF!$D$15:$H$15)+DCF!$H$16*J$19/(1+$B26)^DCF!$D$27+DCF!$C$43)/DCF!$C$45 -> 437.70328 | K26: =(SUMPRODUCT(DCF!$D$18:$H$18/(1+$B26)^DCF!$D$15:$H$15)+DCF!$H$16*K$19/(1+$B26)^DCF!$D$27+DCF!$C$43)/DCF!$C$45 -> 452.03252
B27: =WACC!$C$37+(7-4)*Assumptions!$D$14 -> 0.070378903 | C27: =(SUMPRODUCT(DCF!$D$18:$H$18/(1+$B27)^DCF!$D$15:$H$15)+DCF!$H$16*C$19/(1+$B27)^DCF!$D$27+DCF!$C$43)/DCF!$C$45 -> 334.10985 | D27: =(SUMPRODUCT(DCF!$D$18:$H$18/(1+$B27)^DCF!$D$15:$H$15)+DCF!$H$16*D$19/(1+$B27)^DCF!$D$27+DCF!$C$43)/DCF!$C$45 -> 348.29479 | E27: =(SUMPRODUCT(DCF!$D$18:$H$18/(1+$B27)^DCF!$D$15:$H$15)+DCF!$H$16*E$19/(1+$B27)^DCF!$D$27+DCF!$C$43)/DCF!$C$45 -> 362.47972 | F27: =(SUMPRODUCT(DCF!$D$18:$H$18/(1+$B27)^DCF!$D$15:$H$15)+DCF!$H$16*F$19/(1+$B27)^DCF!$D$27+DCF!$C$43)/DCF!$C$45 -> 376.66465 | G27: =(SUMPRODUCT(DCF!$D$18:$H$18/(1+$B27)^DCF!$D$15:$H$15)+DCF!$H$16*G$19/(1+$B27)^DCF!$D$27+DCF!$C$43)/DCF!$C$45 -> 390.84959 | H27: =(SUMPRODUCT(DCF!$D$18:$H$18/(1+$B27)^DCF!$D$15:$H$15)+DCF!$H$16*H$19/(1+$B27)^DCF!$D$27+DCF!$C$43)/DCF!$C$45 -> 405.03452 | I27: =(SUMPRODUCT(DCF!$D$18:$H$18/(1+$B27)^DCF!$D$15:$H$15)+DCF!$H$16*I$19/(1+$B27)^DCF!$D$27+DCF!$C$43)/DCF!$C$45 -> 419.21945 | J27: =(SUMPRODUCT(DCF!$D$18:$H$18/(1+$B27)^DCF!$D$15:$H$15)+DCF!$H$16*J$19/(1+$B27)^DCF!$D$27+DCF!$C$43)/DCF!$C$45 -> 433.40439 | K27: =(SUMPRODUCT(DCF!$D$18:$H$18/(1+$B27)^DCF!$D$15:$H$15)+DCF!$H$16*K$19/(1+$B27)^DCF!$D$27+DCF!$C$43)/DCF!$C$45 -> 447.58932
B28: =WACC!$C$37+(8-4)*Assumptions!$D$14 -> 0.072878903 | C28: =(SUMPRODUCT(DCF!$D$18:$H$18/(1+$B28)^DCF!$D$15:$H$15)+DCF!$H$16*C$19/(1+$B28)^DCF!$D$27+DCF!$C$43)/DCF!$C$45 -> 330.86043 | D28: =(SUMPRODUCT(DCF!$D$18:$H$18/(1+$B28)^DCF!$D$15:$H$15)+DCF!$H$16*D$19/(1+$B28)^DCF!$D$27+DCF!$C$43)/DCF!$C$45 -> 344.90283 | E28: =(SUMPRODUCT(DCF!$D$18:$H$18/(1+$B28)^DCF!$D$15:$H$15)+DCF!$H$16*E$19/(1+$B28)^DCF!$D$27+DCF!$C$43)/DCF!$C$45 -> 358.94524 | F28: =(SUMPRODUCT(DCF!$D$18:$H$18/(1+$B28)^DCF!$D$15:$H$15)+DCF!$H$16*F$19/(1+$B28)^DCF!$D$27+DCF!$C$43)/DCF!$C$45 -> 372.98765 | G28: =(SUMPRODUCT(DCF!$D$18:$H$18/(1+$B28)^DCF!$D$15:$H$15)+DCF!$H$16*G$19/(1+$B28)^DCF!$D$27+DCF!$C$43)/DCF!$C$45 -> 387.03005 | H28: =(SUMPRODUCT(DCF!$D$18:$H$18/(1+$B28)^DCF!$D$15:$H$15)+DCF!$H$16*H$19/(1+$B28)^DCF!$D$27+DCF!$C$43)/DCF!$C$45 -> 401.07246 | I28: =(SUMPRODUCT(DCF!$D$18:$H$18/(1+$B28)^DCF!$D$15:$H$15)+DCF!$H$16*I$19/(1+$B28)^DCF!$D$27+DCF!$C$43)/DCF!$C$45 -> 415.11487 | J28: =(SUMPRODUCT(DCF!$D$18:$H$18/(1+$B28)^DCF!$D$15:$H$15)+DCF!$H$16*J$19/(1+$B28)^DCF!$D$27+DCF!$C$43)/DCF!$C$45 -> 429.15727 | K28: =(SUMPRODUCT(DCF!$D$18:$H$18/(1+$B28)^DCF!$D$15:$H$15)+DCF!$H$16*K$19/(1+$B28)^DCF!$D$27+DCF!$C$43)/DCF!$C$45 -> 443.19968
B30: ="Current price: CHF "&TEXT(Assumptions!$D$8,"0.00")&" | centre cell = live DCF output (bold box)" -> Current price: CHF 357.00 | centre cell = live DCF output (bold box)

Sheet Charts
B1: Charts
B2: Chart data below is fully linked; charts update with the scenario switch.
B4: Revenue, EBITDA & margin
C5: 2023A | D5: 2024A | E5: 2025A | F5: 2026E | G5: 2027E | H5: 2028E | I5: 2029E | J5: 2030E
B6: Revenue | C6: =Historicals!C11 -> 60441 | D6: =Historicals!D11 -> 62395 | E6: =Historicals!E11 -> 63356 | F6: ='Operating Model'!$D$25 -> 65539.379 | G6: ='Operating Model'!$E$25 -> 68271.506 | H6: ='Operating Model'!$F$25 -> 70927.813 | I6: ='Operating Model'!$G$25 -> 73410.286 | J6: ='Operating Model'!$H$25 -> 75692.458
B7: Adjusted EBITDA | C7: =Historicals!C56 -> 21988 | D7: =Historicals!D56 -> 23504 | E7: =Historicals!E56 -> 24543 | F7: ='Operating Model'!$D$29 -> 25691.437 | G7: ='Operating Model'!$E$29 -> 27035.516 | H7: ='Operating Model'!$F$29 -> 28371.125 | I7: ='Operating Model'!$G$29 -> 29510.935 | J7: ='Operating Model'!$H$29 -> 30579.753
B8: Adj. EBITDA margin | C8: =C7/C6 -> 0.36379279 | D8: =D7/D6 -> 0.37669685 | E8: =E7/E6 -> 0.38738241 | F8: =F7/F6 -> 0.392 | G8: =G7/G6 -> 0.396 | H8: =H7/H6 -> 0.4 | I8: =I7/I6 -> 0.402 | J8: =J7/J6 -> 0.404
B10: UFCF bridge 2026E (waterfall)
B11: Step | C11: Value | D11: Cumulative | E11: Base | F11: Increase | G11: Decrease | H11: Total
B12: Adj. EBITDA | C12: ='Operating Model'!$D$29 -> 25691.437 | D12: =C12 -> 25691.437 | E12: =0 -> 0 | F12: =0 -> 0 | G12: =0 -> 0 | H12: =C12 -> 25691.437
B13: Taxes | C13: ='Operating Model'!$D$34 -> -4221.3914 | D13: =D12+C13 -> 21470.045 | E13: =MIN(D12,D13) -> 21470.045 | F13: =MAX(C13,0) -> 0 | G13: =MAX(-C13,0) -> 4221.3914 | H13: =0 -> 0
B14: Capex | C14: ='Operating Model'!$D$48 -> -5570.8472 | D14: =D13+C14 -> 15899.198 | E14: =MIN(D13,D14) -> 15899.198 | F14: =MAX(C14,0) -> 0 | G14: =MAX(-C14,0) -> 5570.8472 | H14: =0 -> 0
B15: Δ Working capital | C15: ='Operating Model'!$D$49 -> -745.80752 | D15: =D14+C15 -> 15153.39 | E15: =MIN(D14,D15) -> 15153.39 | F15: =MAX(C15,0) -> 0 | G15: =MAX(-C15,0) -> 745.80752 | H15: =0 -> 0
B16: UFCF 2026E | C16: ='Operating Model'!$D$50 -> 15153.39 | D16: =C16 -> 15153.39 | E16: =0 -> 0 | F16: =0 -> 0 | G16: =0 -> 0 | H16: =C16 -> 15153.39
B17: Check: cumulative vs. UFCF | C17: =D15-C16 -> 0
B19: Valuation summary – football field (CHF per share)
B20: Method | C20: Low | D20: High | E20: Bar length
B21: 52-week trading range | C21: =Assumptions!$D$9 -> 254 | D21: =Assumptions!$D$10 -> 375.8 | E21: =D21-C21 -> 121.8
B22: Trading comps (EV / 2026E EBITDA) | C22: =(Assumptions!$D$12*'Operating Model'!$D$29+DCF!$C$43)/DCF!$C$45 -> 306.11218 | D22: =(Assumptions!$D$13*'Operating Model'!$D$29+DCF!$C$43)/DCF!$C$45 -> 402.09513 | E22: =D22-C22 -> 95.982951
B23: DCF – exit multiple (±1 step) | C23: =MIN(Sensitivity!$F$23:$H$25) -> 384.15323 | D23: =MAX(Sensitivity!$F$23:$H$25) -> 421.37196 | E23: =D23-C23 -> 37.218734
B24: DCF – perpetuity growth (±1 step) | C24: =MIN(Sensitivity!$F$10:$H$12) -> 399.46618 | D24: =MAX(Sensitivity!$F$10:$H$12) -> 491.47031 | E24: =D24-C24 -> 92.004132
B25: Current share price | C25: =Assumptions!$D$8 -> 357
B27: Football field note: read the current share price (row 25) against the bars; the 52-week bar brackets the market range.
